Workbook

Sheet Intro
A1: Introduction to Reinforcement Learning
A3: 1. What Is Reinforcement Learning?
A4: Reinforcement Learning (RL) is a computational approach to learning from INTERACTION.
A5: An AGENT takes ACTIONS in an ENVIRONMENT, receives REWARDS, and learns a POLICY to maximize cumulative reward over time.
A6: Unlike supervised learning (given correct answers) or unsupervised learning (find patterns), RL learns by TRIAL AND ERROR.
A7: The central challenge: actions have DELAYED consequences — a good action now may only pay off many steps later.
A9: 2. The Agent-Environment Interaction Loop
A10: At each time step t, the agent observes state s_t, takes action a_t, receives reward r_{t+1}, and transitions to s_{t+1}.
A12: +-----------------------------------+
A13: | ENVIRONMENT |
A14: | (Race Car + Track Physics) |
A15: +-----------------------------------+
... A31: 3. Key Terminology
A32: Term | B32: Symbol | C32: Definition
A33: State | B33: s | C33: A complete description of the current situation | H33: {Cool, Warm, Overheated}
A34: Action | B34: a | C34: A choice the agent can make in a given state | H34: {Slow, Fast}
A35: Reward | B35: r | C35: Immediate scalar feedback after a transition | H35: +1 (slow), +2 (fast), -10 (overheat)
A36: Transition | B36: P(s'|s,a) | C36: Probability of reaching state s' from s via action a | H36: 0.5/0.5 non-terminal; 1.0 terminal
A37: Policy | B37: pi(a|s) | C37: A rule mapping states to actions (the agent's strategy) | H37: e.g. Fast@Cool, Slow@Warm
A38: Episode | B38: s_0,...,s_T | C38: A sequence from start state to terminal state | H38: Cool -> ... -> Overheated
A39: Return | B39: G_t | C39: Cumulative discounted reward from time t onward | H39: G_t = r_{t+1} + gamma*G_{t+1}
A40: Discount | B40: gamma | C40: How much future rewards are worth (0 to 1); gamma=0.9 here | H40: gamma=0.9: future $1 is worth $0.90 today
A41: State Value | B41: V(s) | C41: Expected return starting from state s, following policy pi | H41: V(Cool) = expected total reward from Cool
A42: Action Value | B42: Q(s,a) | C42: Expected return starting from s, taking a, then following pi | H42: Q(Cool,Fast) = exp. reward if Fast then follow pi
A43: Optimal Value | B43: V*(s), Q*(s,a) | C43: Best possible expected return over ALL policies | H43: V*(Cool)=15.5, V*(Warm)=14.5
A44: Optimal Policy | B44: pi*(a|s) | C44: The policy that achieves V*(s) for every state | H44: pi*(Cool)=Fast, pi*(Warm)=Slow
A46: 4. The Mathematical Framework: Bellman Equations
A47: These equations express a recursive relationship: the value of a state depends on immediate reward PLUS the discounted value of the next state.
A49: Equation | B49: Name | C49: Formula
A50: 1 | B50: Bellman Expectation (for V^pi) | C50: V^pi(s) = SUM_a pi(a|s) * SUM_{s'} P(s'|s,a) * [R(s,a,s') + gamma * V^pi(s')] | G50: Value of s under policy pi = expected [reward + discounted future value]
A51: 2 | B51: Bellman Expectation (for Q^pi) | C51: Q^pi(s,a) = SUM_{s'} P(s'|s,a) * [R(s,a,s') + gamma * SUM_{a'} pi(a'|s') * Q^pi(s',a')] | G51: Value of taking action a in state s, then following pi
A52: 3 | B52: Bellman Optimality (for V*) | C52: V*(s) = max_a SUM_{s'} P(s'|s,a) * [R(s,a,s') + gamma * V*(s')] | G52: Optimal value = best action's expected [reward + discounted optimal future]
A53: 4 | B53: Bellman Optimality (for Q*) | C53: Q*(s,a) = SUM_{s'} P(s'|s,a) * [R(s,a,s') + gamma * max_{a'} Q*(s',a')] | G53: Optimal action-value: take a, then act optimally forever after
A54: 5 | B54: V-Q Relationship | C54: V*(s) = max_a Q*(s,a) and pi*(s) = argmax_a Q*(s,a) | G54: Optimal value = best Q; optimal policy = pick the action with highest Q
A55: 6 | B55: Return (recursive) | C55: G_t = r_{t+1} + gamma * G_{t+1} with G_T = r_T (terminal) | G55: Total discounted reward from time t; computed backward from the end
A57: 5. Three Families of Solution Methods
A58: All three converge to V*/Q*/pi* but differ in what they require and how they learn.
A60: Method | B60: Key Idea | C60: Requires Model? | D60: Update Rule
A61: Dynamic Programming (DP) | B61: Sweep over ALL states, apply Bellman update using known P and R | C61: YES (full model P, R) | D61: V(s) <- SUM_a pi(a|s) * SUM_{s'} P(s'|s,a) * [R + gamma*V(s')] | H61: The model itself (no interaction needed)
A62: Monte Carlo (MC) | B62: Play complete episodes, compute actual returns, average them | C62: NO (model-free) | D62: V(s) <- average of all returns G_t observed from first visits to s | H62: Complete episodes (must reach terminal state)
...

Sheet Problem
A1: MDP Race Car — Problem Definition
A3: States (S)
A4: State | B4: Symbol | C4: Terminal?
A5: Cool | B5: C | C5: No
A6: Warm | B6: W | C6: No
A7: Overheated | B7: OH | C7: Yes
A9: Actions (A)
A10: Action | B10: Symbol
A11: Slow | B11: S
A12: Fast | B12: F
A14: Transition Probabilities P(s'|s,a)
A15: s | B15: a | C15: P(s'=C) | D15: P(s'=W) | E15: P(s'=OH) | F15: Sum ✱
A16: Cool | B16: Slow | C16: 0.5 | D16: 0.5 | E16: 0 | F16: =C16+D16+E16
A17: Cool | B17: Fast | C17: 0.5 | D17: 0.5 | E17: 0 | F17: =C17+D17+E17
A18: Warm | B18: Slow | C18: 0.5 | D18: 0.5 | E18: 0 | F18: =C18+D18+E18
A19: Warm | B19: Fast | C19: 0 | D19: 0 | E19: 1 | F19: =C19+D19+E19
A21: Reward Function R(s,a,s')
A22: Condition | B22: R
A23: s' non-terminal, a=Slow | B23: 1
A24: s' non-terminal, a=Fast | B24: 2
A25: s'=Overheated | B25: -10
A27: Parameters
A28: γ (gamma) | B28: 0.9
A29: α (learning rate) | B29: 0.1

Sheet DP-Eval
A1: DP — Policy Evaluation: Synchronous vs In-Place
A2: Synchronous: V_{k+1}(s) uses V_k for ALL states (full previous sweep). In-Place: V(s) uses latest available values within the SAME sweep.
A3: k = iteration (one full sweep). Both converge to the same V^π — in-place is often faster. The Bellman EQUATION describes the fixed point; these are two ALGORITHMS to reach it.
A5: Policy 1: Cautious (Always Slow)
A6: SYNCHRONOUS: V_{k+1}(C) = 0.5·(1+γ·V_k(C)) + 0.5·(1+γ·V_k(W)). V_{k+1}(W) same. Both from PREVIOUS sweep k.
A7: IN-PLACE: V(C) ← 0.5·(1+γ·V_old(C)) + 0.5·(1+γ·V_old(W)). Then V(W) ← 0.5·(1+γ·V_NEW(C)) + 0.5·(1+γ·V_old(W)). Cool updated first!
A8: k | B8: V_k(C) sync ✱ | C8: V_k(W) sync ✱ | D8: V_k(OH) | E8: |ΔV| sync ✱ | G8: V_k(C) inplace ✱ | H8: V_k(W) inplace ✱ | I8: V_k(OH) | J8: |ΔV| inplace ✱ | K8: Diff ✱
A9: 0 | B9: 0 | C9: 0 | D9: 0 | E9: — | G9: 0 | H9: 0 | I9: 0 | J9: — | K9: —
A10: 1 | B10: =0.5*(1+0.9*B9)+0.5*(1+0.9*C9) | C10: =0.5*(1+0.9*B9)+0.5*(1+0.9*C9) | D10: 0 | E10: =MAX(ABS(B10-B9),ABS(C10-C9)) | G10: =0.5*(1+0.9*G9)+0.5*(1+0.9*H9) | H10: =0.5*(1+0.9*G10)+0.5*(1+0.9*H9) | I10: 0 | J10: =MAX(ABS(G10-G9),ABS(H10-H9)) | K10: =MAX(ABS(B10-G10),ABS(C10-H10))
A11: 2 | B11: =0.5*(1+0.9*B10)+0.5*(1+0.9*C10) | C11: =0.5*(1+0.9*B10)+0.5*(1+0.9*C10) | D11: 0 | E11: =MAX(ABS(B11-B10),ABS(C11-C10)) | G11: =0.5*(1+0.9*G10)+0.5*(1+0.9*H10) | H11: =0.5*(1+0.9*G11)+0.5*(1+0.9*H10) | I11: 0 | J11: =MAX(ABS(G11-G10),ABS(H11-H10)) | K11: =MAX(ABS(B11-G11),ABS(C11-H11))
A12: 3 | B12: =0.5*(1+0.9*B11)+0.5*(1+0.9*C11) | C12: =0.5*(1+0.9*B11)+0.5*(1+0.9*C11) | D12: 0 | E12: =MAX(ABS(B12-B11),ABS(C12-C11)) | G12: =0.5*(1+0.9*G11)+0.5*(1+0.9*H11) | H12: =0.5*(1+0.9*G12)+0.5*(1+0.9*H11) | I12: 0 | J12: =MAX(ABS(G12-G11),ABS(H12-H11)) | K12: =MAX(ABS(B12-G12),ABS(C12-H12))
A13: 4 | B13: =0.5*(1+0.9*B12)+0.5*(1+0.9*C12) | C13: =0.5*(1+0.9*B12)+0.5*(1+0.9*C12) | D13: 0 | E13: =MAX(ABS(B13-B12),ABS(C13-C12)) | G13: =0.5*(1+0.9*G12)+0.5*(1+0.9*H12) | H13: =0.5*(1+0.9*G13)+0.5*(1+0.9*H12) | I13: 0 | J13: =MAX(ABS(G13-G12),ABS(H13-H12)) | K13: =MAX(ABS(B13-G13),ABS(C13-H13))
A14: 5 | B14: =0.5*(1+0.9*B13)+0.5*(1+0.9*C13) | C14: =0.5*(1+0.9*B13)+0.5*(1+0.9*C13) | D14: 0 | E14: =MAX(ABS(B14-B13),ABS(C14-C13)) | G14: =0.5*(1+0.9*G13)+0.5*(1+0.9*H13) | H14: =0.5*(1+0.9*G14)+0.5*(1+0.9*H13) | I14: 0 | J14: =MAX(ABS(G14-G13),ABS(H14-H13)) | K14: =MAX(ABS(B14-G14),ABS(C14-H14))
A15: 6 | B15: =0.5*(1+0.9*B14)+0.5*(1+0.9*C14) | C15: =0.5*(1+0.9*B14)+0.5*(1+0.9*C14) | D15: 0 | E15: =MAX(ABS(B15-B14),ABS(C15-C14)) | G15: =0.5*(1+0.9*G14)+0.5*(1+0.9*H14) | H15: =0.5*(1+0.9*G15)+0.5*(1+0.9*H14) | I15: 0 | J15: =MAX(ABS(G15-G14),ABS(H15-H14)) | K15: =MAX(ABS(B15-G15),ABS(C15-H15))
A16: 7 | B16: =0.5*(1+0.9*B15)+0.5*(1+0.9*C15) | C16: =0.5*(1+0.9*B15)+0.5*(1+0.9*C15) | D16: 0 | E16: =MAX(ABS(B16-B15),ABS(C16-C15)) | G16: =0.5*(1+0.9*G15)+0.5*(1+0.9*H15) | H16: =0.5*(1+0.9*G16)+0.5*(1+0.9*H15) | I16: 0 | J16: =MAX(ABS(G16-G15),ABS(H16-H15)) | K16: =MAX(ABS(B16-G16),ABS(C16-H16))
A17: 8 | B17: =0.5*(1+0.9*B16)+0.5*(1+0.9*C16) | C17: =0.5*(1+0.9*B16)+0.5*(1+0.9*C16) | D17: 0 | E17: =MAX(ABS(B17-B16),ABS(C17-C16)) | G17: =0.5*(1+0.9*G16)+0.5*(1+0.9*H16) | H17: =0.5*(1+0.9*G17)+0.5*(1+0.9*H16) | I17: 0 | J17: =MAX(ABS(G17-G16),ABS(H17-H16)) | K17: =MAX(ABS(B17-G17),ABS(C17-H17))
A18: 9 | B18: =0.5*(1+0.9*B17)+0.5*(1+0.9*C17) | C18: =0.5*(1+0.9*B17)+0.5*(1+0.9*C17) | D18: 0 | E18: =MAX(ABS(B18-B17),ABS(C18-C17)) | G18: =0.5*(1+0.9*G17)+0.5*(1+0.9*H17) | H18: =0.5*(1+0.9*G18)+0.5*(1+0.9*H17) | I18: 0 | J18: =MAX(ABS(G18-G17),ABS(H18-H17)) | K18: =MAX(ABS(B18-G18),ABS(C18-H18))
A19: 10 | B19: =0.5*(1+0.9*B18)+0.5*(1+0.9*C18) | C19: =0.5*(1+0.9*B18)+0.5*(1+0.9*C18) | D19: 0 | E19: =MAX(ABS(B19-B18),ABS(C19-C18)) | G19: =0.5*(1+0.9*G18)+0.5*(1+0.9*H18) | H19: =0.5*(1+0.9*G19)+0.5*(1+0.9*H18) | I19: 0 | J19: =MAX(ABS(G19-G18),ABS(H19-H18)) | K19: =MAX(ABS(B19-G19),ABS(C19-H19))
A20: 11 | B20: =0.5*(1+0.9*B19)+0.5*(1+0.9*C19) | C20: =0.5*(1+0.9*B19)+0.5*(1+0.9*C19) | D20: 0 | E20: =MAX(ABS(B20-B19),ABS(C20-C19)) | G20: =0.5*(1+0.9*G19)+0.5*(1+0.9*H19) | H20: =0.5*(1+0.9*G20)+0.5*(1+0.9*H19) | I20: 0 | J20: =MAX(ABS(G20-G19),ABS(H20-H19)) | K20: =MAX(ABS(B20-G20),ABS(C20-H20))
A21: 12 | B21: =0.5*(1+0.9*B20)+0.5*(1+0.9*C20) | C21: =0.5*(1+0.9*B20)+0.5*(1+0.9*C20) | D21: 0 | E21: =MAX(ABS(B21-B20),ABS(C21-C20)) | G21: =0.5*(1+0.9*G20)+0.5*(1+0.9*H20) | H21: =0.5*(1+0.9*G21)+0.5*(1+0.9*H20) | I21: 0 | J21: =MAX(ABS(G21-G20),ABS(H21-H20)) | K21: =MAX(ABS(B21-G21),ABS(C21-H21))
... A59: 50 | B59: =0.5*(1+0.9*B58)+0.5*(1+0.9*C58) | C59: =0.5*(1+0.9*B58)+0.5*(1+0.9*C58) | D59: 0 | E59: =MAX(ABS(B59-B58),ABS(C59-C58)) | G59: =0.5*(1+0.9*G58)+0.5*(1+0.9*H58) | H59: =0.5*(1+0.9*G59)+0.5*(1+0.9*H58) | I59: 0 | J59: =MAX(ABS(G59-G58),ABS(H59-H58)) | K59: =MAX(ABS(B59-G59),ABS(C59-H59))
A62: Policy 2: Optimal (Fast@Cool, Slow@Warm)
A63: SYNCHRONOUS: V_{k+1}(C) = 0.5·(2+γ·V_k(C))+0.5·(2+γ·V_k(W)). V_{k+1}(W) = 0.5·(1+γ·V_k(C))+0.5·(1+γ·V_k(W)). Both from sweep k.
A64: IN-PLACE: V(C) ← fast formula with V_old. Then V(W) ← slow formula using V_NEW(C) + V_old(W). Warm sees Cool's updated value!
A65: k | B65: V_k(C) sync ✱ | C65: V_k(W) sync ✱ | D65: V_k(OH) | E65: |ΔV| sync ✱ | G65: V_k(C) inplace ✱ | H65: V_k(W) inplace ✱ | I65: V_k(OH) | J65: |ΔV| inplace ✱ | K65: Diff ✱
A66: 0 | B66: 0 | C66: 0 | D66: 0 | E66: — | G66: 0 | H66: 0 | I66: 0 | J66: — | K66: —
A67: 1 | B67: =0.5*(2+0.9*B66)+0.5*(2+0.9*C66) | C67: =0.5*(1+0.9*B66)+0.5*(1+0.9*C66) | D67: 0 | E67: =MAX(ABS(B67-B66),ABS(C67-C66)) | G67: =0.5*(2+0.9*G66)+0.5*(2+0.9*H66) | H67: =0.5*(1+0.9*G67)+0.5*(1+0.9*H66) | I67: 0 | J67: =MAX(ABS(G67-G66),ABS(H67-H66)) | K67: =MAX(ABS(B67-G67),ABS(C67-H67))
A68: 2 | B68: =0.5*(2+0.9*B67)+0.5*(2+0.9*C67) | C68: =0.5*(1+0.9*B67)+0.5*(1+0.9*C67) | D68: 0 | E68: =MAX(ABS(B68-B67),ABS(C68-C67)) | G68: =0.5*(2+0.9*G67)+0.5*(2+0.9*H67) | H68: =0.5*(1+0.9*G68)+0.5*(1+0.9*H67) | I68: 0 | J68: =MAX(ABS(G68-G67),ABS(H68-H67)) | K68: =MAX(ABS(B68-G68),ABS(C68-H68))
A69: 3 | B69: =0.5*(2+0.9*B68)+0.5*(2+0.9*C68) | C69: =0.5*(1+0.9*B68)+0.5*(1+0.9*C68) | D69: 0 | E69: =MAX(ABS(B69-B68),ABS(C69-C68)) | G69: =0.5*(2+0.9*G68)+0.5*(2+0.9*H68) | H69: =0.5*(1+0.9*G69)+0.5*(1+0.9*H68) | I69: 0 | J69: =MAX(ABS(G69-G68),ABS(H69-H68)) | K69: =MAX(ABS(B69-G69),ABS(C69-H69))
A70: 4 | B70: =0.5*(2+0.9*B69)+0.5*(2+0.9*C69) | C70: =0.5*(1+0.9*B69)+0.5*(1+0.9*C69) | D70: 0 | E70: =MAX(ABS(B70-B69),ABS(C70-C69)) | G70: =0.5*(2+0.9*G69)+0.5*(2+0.9*H69) | H70: =0.5*(1+0.9*G70)+0.5*(1+0.9*H69) | I70: 0 | J70: =MAX(ABS(G70-G69),ABS(H70-H69)) | K70: =MAX(ABS(B70-G70),ABS(C70-H70))
A71: 5 | B71: =0.5*(2+0.9*B70)+0.5*(2+0.9*C70) | C71: =0.5*(1+0.9*B70)+0.5*(1+0.9*C70) | D71: 0 | E71: =MAX(ABS(B71-B70),ABS(C71-C70)) | G71: =0.5*(2+0.9*G70)+0.5*(2+0.9*H70) | H71: =0.5*(1+0.9*G71)+0.5*(1+0.9*H70) | I71: 0 | J71: =MAX(ABS(G71-G70),ABS(H71-H70)) | K71: =MAX(ABS(B71-G71),ABS(C71-H71))
A72: 6 | B72: =0.5*(2+0.9*B71)+0.5*(2+0.9*C71) | C72: =0.5*(1+0.9*B71)+0.5*(1+0.9*C71) | D72: 0 | E72: =MAX(ABS(B72-B71),ABS(C72-C71)) | G72: =0.5*(2+0.9*G71)+0.5*(2+0.9*H71) | H72: =0.5*(1+0.9*G72)+0.5*(1+0.9*H71) | I72: 0 | J72: =MAX(ABS(G72-G71),ABS(H72-H71)) | K72: =MAX(ABS(B72-G72),ABS(C72-H72))
A73: 7 | B73: =0.5*(2+0.9*B72)+0.5*(2+0.9*C72) | C73: =0.5*(1+0.9*B72)+0.5*(1+0.9*C72) | D73: 0 | E73: =MAX(ABS(B73-B72),ABS(C73-C72)) | G73: =0.5*(2+0.9*G72)+0.5*(2+0.9*H72) | H73: =0.5*(1+0.9*G73)+0.5*(1+0.9*H72) | I73: 0 | J73: =MAX(ABS(G73-G72),ABS(H73-H72)) | K73: =MAX(ABS(B73-G73),ABS(C73-H73))
A74: 8 | B74: =0.5*(2+0.9*B73)+0.5*(2+0.9*C73) | C74: =0.5*(1+0.9*B73)+0.5*(1+0.9*C73) | D74: 0 | E74: =MAX(ABS(B74-B73),ABS(C74-C73)) | G74: =0.5*(2+0.9*G73)+0.5*(2+0.9*H73) | H74: =0.5*(1+0.9*G74)+0.5*(1+0.9*H73) | I74: 0 | J74: =MAX(ABS(G74-G73),ABS(H74-H73)) | K74: =MAX(ABS(B74-G74),ABS(C74-H74))
A75: 9 | B75: =0.5*(2+0.9*B74)+0.5*(2+0.9*C74) | C75: =0.5*(1+0.9*B74)+0.5*(1+0.9*C74) | D75: 0 | E75: =MAX(ABS(B75-B74),ABS(C75-C74)) | G75: =0.5*(2+0.9*G74)+0.5*(2+0.9*H74) | H75: =0.5*(1+0.9*G75)+0.5*(1+0.9*H74) | I75: 0 | J75: =MAX(ABS(G75-G74),ABS(H75-H74)) | K75: =MAX(ABS(B75-G75),ABS(C75-H75))
A76: 10 | B76: =0.5*(2+0.9*B75)+0.5*(2+0.9*C75) | C76: =0.5*(1+0.9*B75)+0.5*(1+0.9*C75) | D76: 0 | E76: =MAX(ABS(B76-B75),ABS(C76-C75)) | G76: =0.5*(2+0.9*G75)+0.5*(2+0.9*H75) | H76: =0.5*(1+0.9*G76)+0.5*(1+0.9*H75) | I76: 0 | J76: =MAX(ABS(G76-G75),ABS(H76-H75)) | K76: =MAX(ABS(B76-G76),ABS(C76-H76))
A77: 11 | B77: =0.5*(2+0.9*B76)+0.5*(2+0.9*C76) | C77: =0.5*(1+0.9*B76)+0.5*(1+0.9*C76) | D77: 0 | E77: =MAX(ABS(B77-B76),ABS(C77-C76)) | G77: =0.5*(2+0.9*G76)+0.5*(2+0.9*H76) | H77: =0.5*(1+0.9*G77)+0.5*(1+0.9*H76) | I77: 0 | J77: =MAX(ABS(G77-G76),ABS(H77-H76)) | K77: =MAX(ABS(B77-G77),ABS(C77-H77))
A78: 12 | B78: =0.5*(2+0.9*B77)+0.5*(2+0.9*C77) | C78: =0.5*(1+0.9*B77)+0.5*(1+0.9*C77) | D78: 0 | E78: =MAX(ABS(B78-B77),ABS(C78-C77)) | G78: =0.5*(2+0.9*G77)+0.5*(2+0.9*H77) | H78: =0.5*(1+0.9*G78)+0.5*(1+0.9*H77) | I78: 0 | J78: =MAX(ABS(G78-G77),ABS(H78-H77)) | K78: =MAX(ABS(B78-G78),ABS(C78-H78))
... A116: 50 | B116: =0.5*(2+0.9*B115)+0.5*(2+0.9*C115) | C116: =0.5*(1+0.9*B115)+0.5*(1+0.9*C115) | D116: 0 | E116: =MAX(ABS(B116-B115),ABS(C116-C115)) | G116: =0.5*(2+0.9*G115)+0.5*(2+0.9*H115) | H116: =0.5*(1+0.9*G116)+0.5*(1+0.9*H115) | I116: 0 | J116: =MAX(ABS(G116-G115),ABS(H116-H115)) | K116: =MAX(ABS(B116-G116),ABS(C116-H116))
A119: Policy 3: Aggressive (Always Fast)
...

Sheet DP-VI
A1: DP — Value Iteration: Synchronous vs In-Place
A2: Synchronous: V_{k+1}(s) = max_a Σ P·[R+γ·V_k(s')] using ALL values from previous sweep k.
A3: In-Place: V(s) ← max_a Σ P·[R+γ·V(s')] using latest available V — Cool updated first, Warm uses NEW Cool within same sweep.
A4: Both converge to the same V*, Q*, π* — in-place often converges faster (fewer iterations for same |ΔV|).
A6: Synchronous Value Iteration
A7: k | B7: Q(C,S) ✱ | C7: Q(C,F) ✱ | D7: V*(C) ✱ | E7: Q(W,S) ✱ | F7: Q(W,F) ✱ | G7: V*(W) ✱ | H7: V*(OH) | I7: π*(C) ✱ | J7: π*(W) ✱ | K7: |ΔV| ✱
A8: 0 | B8: 0 | C8: 0 | D8: 0 | E8: 0 | F8: 0 | G8: 0 | H8: 0 | I8: — | J8: — | K8: —
A9: 1 | B9: =0.5*(1+0.9*D8)+0.5*(1+0.9*G8) | C9: =0.5*(2+0.9*D8)+0.5*(2+0.9*G8) | D9: =MAX(B9,C9) | E9: =0.5*(1+0.9*D8)+0.5*(1+0.9*G8) | F9: =1*(-10+0.9*H8) | G9: =MAX(E9,F9) | H9: 0 | I9: =IF(C9>=B9,"Fast","Slow") | J9: =IF(F9>=E9,"Fast","Slow") | K9: =MAX(ABS(D9-D8),ABS(G9-G8))
A10: 2 | B10: =0.5*(1+0.9*D9)+0.5*(1+0.9*G9) | C10: =0.5*(2+0.9*D9)+0.5*(2+0.9*G9) | D10: =MAX(B10,C10) | E10: =0.5*(1+0.9*D9)+0.5*(1+0.9*G9) | F10: =1*(-10+0.9*H9) | G10: =MAX(E10,F10) | H10: 0 | I10: =IF(C10>=B10,"Fast","Slow") | J10: =IF(F10>=E10,"Fast","Slow") | K10: =MAX(ABS(D10-D9),ABS(G10-G9))
A11: 3 | B11: =0.5*(1+0.9*D10)+0.5*(1+0.9*G10) | C11: =0.5*(2+0.9*D10)+0.5*(2+0.9*G10) | D11: =MAX(B11,C11) | E11: =0.5*(1+0.9*D10)+0.5*(1+0.9*G10) | F11: =1*(-10+0.9*H10) | G11: =MAX(E11,F11) | H11: 0 | I11: =IF(C11>=B11,"Fast","Slow") | J11: =IF(F11>=E11,"Fast","Slow") | K11: =MAX(ABS(D11-D10),ABS(G11-G10))
A12: 4 | B12: =0.5*(1+0.9*D11)+0.5*(1+0.9*G11) | C12: =0.5*(2+0.9*D11)+0.5*(2+0.9*G11) | D12: =MAX(B12,C12) | E12: =0.5*(1+0.9*D11)+0.5*(1+0.9*G11) | F12: =1*(-10+0.9*H11) | G12: =MAX(E12,F12) | H12: 0 | I12: =IF(C12>=B12,"Fast","Slow") | J12: =IF(F12>=E12,"Fast","Slow") | K12: =MAX(ABS(D12-D11),ABS(G12-G11))
A13: 5 | B13: =0.5*(1+0.9*D12)+0.5*(1+0.9*G12) | C13: =0.5*(2+0.9*D12)+0.5*(2+0.9*G12) | D13: =MAX(B13,C13) | E13: =0.5*(1+0.9*D12)+0.5*(1+0.9*G12) | F13: =1*(-10+0.9*H12) | G13: =MAX(E13,F13) | H13: 0 | I13: =IF(C13>=B13,"Fast","Slow") | J13: =IF(F13>=E13,"Fast","Slow") | K13: =MAX(ABS(D13-D12),ABS(G13-G12))
A14: 6 | B14: =0.5*(1+0.9*D13)+0.5*(1+0.9*G13) | C14: =0.5*(2+0.9*D13)+0.5*(2+0.9*G13) | D14: =MAX(B14,C14) | E14: =0.5*(1+0.9*D13)+0.5*(1+0.9*G13) | F14: =1*(-10+0.9*H13) | G14: =MAX(E14,F14) | H14: 0 | I14: =IF(C14>=B14,"Fast","Slow") | J14: =IF(F14>=E14,"Fast","Slow") | K14: =MAX(ABS(D14-D13),ABS(G14-G13))
A15: 7 | B15: =0.5*(1+0.9*D14)+0.5*(1+0.9*G14) | C15: =0.5*(2+0.9*D14)+0.5*(2+0.9*G14) | D15: =MAX(B15,C15) | E15: =0.5*(1+0.9*D14)+0.5*(1+0.9*G14) | F15: =1*(-10+0.9*H14) | G15: =MAX(E15,F15) | H15: 0 | I15: =IF(C15>=B15,"Fast","Slow") | J15: =IF(F15>=E15,"Fast","Slow") | K15: =MAX(ABS(D15-D14),ABS(G15-G14))
A16: 8 | B16: =0.5*(1+0.9*D15)+0.5*(1+0.9*G15) | C16: =0.5*(2+0.9*D15)+0.5*(2+0.9*G15) | D16: =MAX(B16,C16) | E16: =0.5*(1+0.9*D15)+0.5*(1+0.9*G15) | F16: =1*(-10+0.9*H15) | G16: =MAX(E16,F16) | H16: 0 | I16: =IF(C16>=B16,"Fast","Slow") | J16: =IF(F16>=E16,"Fast","Slow") | K16: =MAX(ABS(D16-D15),ABS(G16-G15))
A17: 9 | B17: =0.5*(1+0.9*D16)+0.5*(1+0.9*G16) | C17: =0.5*(2+0.9*D16)+0.5*(2+0.9*G16) | D17: =MAX(B17,C17) | E17: =0.5*(1+0.9*D16)+0.5*(1+0.9*G16) | F17: =1*(-10+0.9*H16) | G17: =MAX(E17,F17) | H17: 0 | I17: =IF(C17>=B17,"Fast","Slow") | J17: =IF(F17>=E17,"Fast","Slow") | K17: =MAX(ABS(D17-D16),ABS(G17-G16))
A18: 10 | B18: =0.5*(1+0.9*D17)+0.5*(1+0.9*G17) | C18: =0.5*(2+0.9*D17)+0.5*(2+0.9*G17) | D18: =MAX(B18,C18) | E18: =0.5*(1+0.9*D17)+0.5*(1+0.9*G17) | F18: =1*(-10+0.9*H17) | G18: =MAX(E18,F18) | H18: 0 | I18: =IF(C18>=B18,"Fast","Slow") | J18: =IF(F18>=E18,"Fast","Slow") | K18: =MAX(ABS(D18-D17),ABS(G18-G17))
A19: 11 | B19: =0.5*(1+0.9*D18)+0.5*(1+0.9*G18) | C19: =0.5*(2+0.9*D18)+0.5*(2+0.9*G18) | D19: =MAX(B19,C19) | E19: =0.5*(1+0.9*D18)+0.5*(1+0.9*G18) | F19: =1*(-10+0.9*H18) | G19: =MAX(E19,F19) | H19: 0 | I19: =IF(C19>=B19,"Fast","Slow") | J19: =IF(F19>=E19,"Fast","Slow") | K19: =MAX(ABS(D19-D18),ABS(G19-G18))
A20: 12 | B20: =0.5*(1+0.9*D19)+0.5*(1+0.9*G19) | C20: =0.5*(2+0.9*D19)+0.5*(2+0.9*G19) | D20: =MAX(B20,C20) | E20: =0.5*(1+0.9*D19)+0.5*(1+0.9*G19) | F20: =1*(-10+0.9*H19) | G20: =MAX(E20,F20) | H20: 0 | I20: =IF(C20>=B20,"Fast","Slow") | J20: =IF(F20>=E20,"Fast","Slow") | K20: =MAX(ABS(D20-D19),ABS(G20-G19))
... A58: 50 | B58: =0.5*(1+0.9*D57)+0.5*(1+0.9*G57) | C58: =0.5*(2+0.9*D57)+0.5*(2+0.9*G57) | D58: =MAX(B58,C58) | E58: =0.5*(1+0.9*D57)+0.5*(1+0.9*G57) | F58: =1*(-10+0.9*H57) | G58: =MAX(E58,F58) | H58: 0 | I58: =IF(C58>=B58,"Fast","Slow") | J58: =IF(F58>=E58,"Fast","Slow") | K58: =MAX(ABS(D58-D57),ABS(G58-G57))
A61: In-Place Value Iteration (Cool updated first, then Warm uses new Cool)
A62: k | B62: Q(C,S) | C62: Q(C,F) | D62: V*(C) | E62: Q(W,S) | F62: Q(W,F) | G62: V*(W) | H62: V*(OH) | I62: pi*(C) | J62: pi*(W) | K62: |DV|
A63: 0 | B63: 0 | C63: 0 | D63: 0 | E63: 0 | F63: 0 | G63: 0 | H63: 0 | I63: --- | J63: --- | K63: ---
A64: 1 | B64: =0.5*(1+0.9*D63)+0.5*(1+0.9*G63) | C64: =0.5*(2+0.9*D63)+0.5*(2+0.9*G63) | D64: =MAX(B64,C64) | E64: =0.5*(1+0.9*D64)+0.5*(1+0.9*G63) | F64: =1*(-10+0.9*H63) | G64: =MAX(E64,F64) | H64: 0 | I64: =IF(C64>=B64,"Fast","Slow") | J64: =IF(F64>=E64,"Fast","Slow") | K64: =MAX(ABS(D64-D63),ABS(G64-G63))
A65: 2 | B65: =0.5*(1+0.9*D64)+0.5*(1+0.9*G64) | C65: =0.5*(2+0.9*D64)+0.5*(2+0.9*G64) | D65: =MAX(B65,C65) | E65: =0.5*(1+0.9*D65)+0.5*(1+0.9*G64) | F65: =1*(-10+0.9*H64) | G65: =MAX(E65,F65) | H65: 0 | I65: =IF(C65>=B65,"Fast","Slow") | J65: =IF(F65>=E65,"Fast","Slow") | K65: =MAX(ABS(D65-D64),ABS(G65-G64))
A66: 3 | B66: =0.5*(1+0.9*D65)+0.5*(1+0.9*G65) | C66: =0.5*(2+0.9*D65)+0.5*(2+0.9*G65) | D66: =MAX(B66,C66) | E66: =0.5*(1+0.9*D66)+0.5*(1+0.9*G65) | F66: =1*(-10+0.9*H65) | G66: =MAX(E66,F66) | H66: 0 | I66: =IF(C66>=B66,"Fast","Slow") | J66: =IF(F66>=E66,"Fast","Slow") | K66: =MAX(ABS(D66-D65),ABS(G66-G65))
A67: 4 | B67: =0.5*(1+0.9*D66)+0.5*(1+0.9*G66) | C67: =0.5*(2+0.9*D66)+0.5*(2+0.9*G66) | D67: =MAX(B67,C67) | E67: =0.5*(1+0.9*D67)+0.5*(1+0.9*G66) | F67: =1*(-10+0.9*H66) | G67: =MAX(E67,F67) | H67: 0 | I67: =IF(C67>=B67,"Fast","Slow") | J67: =IF(F67>=E67,"Fast","Slow") | K67: =MAX(ABS(D67-D66),ABS(G67-G66))
A68: 5 | B68: =0.5*(1+0.9*D67)+0.5*(1+0.9*G67) | C68: =0.5*(2+0.9*D67)+0.5*(2+0.9*G67) | D68: =MAX(B68,C68) | E68: =0.5*(1+0.9*D68)+0.5*(1+0.9*G67) | F68: =1*(-10+0.9*H67) | G68: =MAX(E68,F68) | H68: 0 | I68: =IF(C68>=B68,"Fast","Slow") | J68: =IF(F68>=E68,"Fast","Slow") | K68: =MAX(ABS(D68-D67),ABS(G68-G67))
A69: 6 | B69: =0.5*(1+0.9*D68)+0.5*(1+0.9*G68) | C69: =0.5*(2+0.9*D68)+0.5*(2+0.9*G68) | D69: =MAX(B69,C69) | E69: =0.5*(1+0.9*D69)+0.5*(1+0.9*G68) | F69: =1*(-10+0.9*H68) | G69: =MAX(E69,F69) | H69: 0 | I69: =IF(C69>=B69,"Fast","Slow") | J69: =IF(F69>=E69,"Fast","Slow") | K69: =MAX(ABS(D69-D68),ABS(G69-G68))
A70: 7 | B70: =0.5*(1+0.9*D69)+0.5*(1+0.9*G69) | C70: =0.5*(2+0.9*D69)+0.5*(2+0.9*G69) | D70: =MAX(B70,C70) | E70: =0.5*(1+0.9*D70)+0.5*(1+0.9*G69) | F70: =1*(-10+0.9*H69) | G70: =MAX(E70,F70) | H70: 0 | I70: =IF(C70>=B70,"Fast","Slow") | J70: =IF(F70>=E70,"Fast","Slow") | K70: =MAX(ABS(D70-D69),ABS(G70-G69))
A71: 8 | B71: =0.5*(1+0.9*D70)+0.5*(1+0.9*G70) | C71: =0.5*(2+0.9*D70)+0.5*(2+0.9*G70) | D71: =MAX(B71,C71) | E71: =0.5*(1+0.9*D71)+0.5*(1+0.9*G70) | F71: =1*(-10+0.9*H70) | G71: =MAX(E71,F71) | H71: 0 | I71: =IF(C71>=B71,"Fast","Slow") | J71: =IF(F71>=E71,"Fast","Slow") | K71: =MAX(ABS(D71-D70),ABS(G71-G70))
A72: 9 | B72: =0.5*(1+0.9*D71)+0.5*(1+0.9*G71) | C72: =0.5*(2+0.9*D71)+0.5*(2+0.9*G71) | D72: =MAX(B72,C72) | E72: =0.5*(1+0.9*D72)+0.5*(1+0.9*G71) | F72: =1*(-10+0.9*H71) | G72: =MAX(E72,F72) | H72: 0 | I72: =IF(C72>=B72,"Fast","Slow") | J72: =IF(F72>=E72,"Fast","Slow") | K72: =MAX(ABS(D72-D71),ABS(G72-G71))
A73: 10 | B73: =0.5*(1+0.9*D72)+0.5*(1+0.9*G72) | C73: =0.5*(2+0.9*D72)+0.5*(2+0.9*G72) | D73: =MAX(B73,C73) | E73: =0.5*(1+0.9*D73)+0.5*(1+0.9*G72) | F73: =1*(-10+0.9*H72) | G73: =MAX(E73,F73) | H73: 0 | I73: =IF(C73>=B73,"Fast","Slow") | J73: =IF(F73>=E73,"Fast","Slow") | K73: =MAX(ABS(D73-D72),ABS(G73-G72))
A74: 11 | B74: =0.5*(1+0.9*D73)+0.5*(1+0.9*G73) | C74: =0.5*(2+0.9*D73)+0.5*(2+0.9*G73) | D74: =MAX(B74,C74) | E74: =0.5*(1+0.9*D74)+0.5*(1+0.9*G73) | F74: =1*(-10+0.9*H73) | G74: =MAX(E74,F74) | H74: 0 | I74: =IF(C74>=B74,"Fast","Slow") | J74: =IF(F74>=E74,"Fast","Slow") | K74: =MAX(ABS(D74-D73),ABS(G74-G73))
A75: 12 | B75: =0.5*(1+0.9*D74)+0.5*(1+0.9*G74) | C75: =0.5*(2+0.9*D74)+0.5*(2+0.9*G74) | D75: =MAX(B75,C75) | E75: =0.5*(1+0.9*D75)+0.5*(1+0.9*G74) | F75: =1*(-10+0.9*H74) | G75: =MAX(E75,F75) | H75: 0 | I75: =IF(C75>=B75,"Fast","Slow") | J75: =IF(F75>=E75,"Fast","Slow") | K75: =MAX(ABS(D75-D74),ABS(G75-G74))
... A113: 50 | B113: =0.5*(1+0.9*D112)+0.5*(1+0.9*G112) | C113: =0.5*(2+0.9*D112)+0.5*(2+0.9*G112) | D113: =MAX(B113,C113) | E113: =0.5*(1+0.9*D113)+0.5*(1+0.9*G112) | F113: =1*(-10+0.9*H112) | G113: =MAX(E113,F113) | H113: 0 | I113: =IF(C113>=B113,"Fast","Slow") | J113: =IF(F113>=E113,"Fast","Slow") | K113: =MAX(ABS(D113-D112),ABS(G113-G112))
A115: Converged Values Comparison
B116: V*(Cool) | C116: V*(Warm) | D116: Match?
A117: Synchronous | B117: =D58 | C117: =G58
A118: In-Place | B118: =D113 | C118: =G113
...

Sheet Convergence
A1: V* Convergence -- Synchronous vs In-Place approaching true V*
A2: Analytical: V*(Cool)=15.5, V*(Warm)=14.5. |DV| shrinks by ~gamma=0.9 each sweep (contraction mapping).
A3: In-place converges faster: Warm immediately benefits from Cool update within the same sweep.
A5: k | B5: V*(C) sync | C5: V*(W) sync | D5: |err C| sync | E5: |err W| sync | F5: |DV| sync | G5: % conv sync | I5: V*(C) inp | J5: V*(W) inp | K5: |err C| inp | L5: |err W| inp | M5: |DV| inp | N5: % conv inp
A6: 0 | B6: 0 | C6: 0 | D6: =ABS(B6-15.5) | E6: =ABS(C6-14.5) | F6: --- | G6: =1-MAX(D6,E6)/15.5 | I6: 0 | J6: 0 | K6: =ABS(I6-15.5) | L6: =ABS(J6-14.5) | M6: --- | N6: =1-MAX(K6,L6)/15.5
A7: 1 | B7: ='DP-VI'!D9 | C7: ='DP-VI'!G9 | D7: =ABS(B7-15.5) | E7: =ABS(C7-14.5) | F7: =MAX(ABS(B7-B6),ABS(C7-C6)) | G7: =1-MAX(D7,E7)/15.5 | I7: ='DP-VI'!D64 | J7: ='DP-VI'!G64 | K7: =ABS(I7-15.5) | L7: =ABS(J7-14.5) | M7: =MAX(ABS(I7-I6),ABS(J7-J6)) | N7: =1-MAX(K7,L7)/15.5
A8: 2 | B8: ='DP-VI'!D10 | C8: ='DP-VI'!G10 | D8: =ABS(B8-15.5) | E8: =ABS(C8-14.5) | F8: =MAX(ABS(B8-B7),ABS(C8-C7)) | G8: =1-MAX(D8,E8)/15.5 | I8: ='DP-VI'!D65 | J8: ='DP-VI'!G65 | K8: =ABS(I8-15.5) | L8: =ABS(J8-14.5) | M8: =MAX(ABS(I8-I7),ABS(J8-J7)) | N8: =1-MAX(K8,L8)/15.5
A9: 3 | B9: ='DP-VI'!D11 | C9: ='DP-VI'!G11 | D9: =ABS(B9-15.5) | E9: =ABS(C9-14.5) | F9: =MAX(ABS(B9-B8),ABS(C9-C8)) | G9: =1-MAX(D9,E9)/15.5 | I9: ='DP-VI'!D66 | J9: ='DP-VI'!G66 | K9: =ABS(I9-15.5) | L9: =ABS(J9-14.5) | M9: =MAX(ABS(I9-I8),ABS(J9-J8)) | N9: =1-MAX(K9,L9)/15.5
A10: 4 | B10: ='DP-VI'!D12 | C10: ='DP-VI'!G12 | D10: =ABS(B10-15.5) | E10: =ABS(C10-14.5) | F10: =MAX(ABS(B10-B9),ABS(C10-C9)) | G10: =1-MAX(D10,E10)/15.5 | I10: ='DP-VI'!D67 | J10: ='DP-VI'!G67 | K10: =ABS(I10-15.5) | L10: =ABS(J10-14.5) | M10: =MAX(ABS(I10-I9),ABS(J10-J9)) | N10: =1-MAX(K10,L10)/15.5
A11: 5 | B11: ='DP-VI'!D13 | C11: ='DP-VI'!G13 | D11: =ABS(B11-15.5) | E11: =ABS(C11-14.5) | F11: =MAX(ABS(B11-B10),ABS(C11-C10)) | G11: =1-MAX(D11,E11)/15.5 | I11: ='DP-VI'!D68 | J11: ='DP-VI'!G68 | K11: =ABS(I11-15.5) | L11: =ABS(J11-14.5) | M11: =MAX(ABS(I11-I10),ABS(J11-J10)) | N11: =1-MAX(K11,L11)/15.5
A12: 6 | B12: ='DP-VI'!D14 | C12: ='DP-VI'!G14 | D12: =ABS(B12-15.5) | E12: =ABS(C12-14.5) | F12: =MAX(ABS(B12-B11),ABS(C12-C11)) | G12: =1-MAX(D12,E12)/15.5 | I12: ='DP-VI'!D69 | J12: ='DP-VI'!G69 | K12: =ABS(I12-15.5) | L12: =ABS(J12-14.5) | M12: =MAX(ABS(I12-I11),ABS(J12-J11)) | N12: =1-MAX(K12,L12)/15.5
A13: 7 | B13: ='DP-VI'!D15 | C13: ='DP-VI'!G15 | D13: =ABS(B13-15.5) | E13: =ABS(C13-14.5) | F13: =MAX(ABS(B13-B12),ABS(C13-C12)) | G13: =1-MAX(D13,E13)/15.5 | I13: ='DP-VI'!D70 | J13: ='DP-VI'!G70 | K13: =ABS(I13-15.5) | L13: =ABS(J13-14.5) | M13: =MAX(ABS(I13-I12),ABS(J13-J12)) | N13: =1-MAX(K13,L13)/15.5
A14: 8 | B14: ='DP-VI'!D16 | C14: ='DP-VI'!G16 | D14: =ABS(B14-15.5) | E14: =ABS(C14-14.5) | F14: =MAX(ABS(B14-B13),ABS(C14-C13)) | G14: =1-MAX(D14,E14)/15.5 | I14: ='DP-VI'!D71 | J14: ='DP-VI'!G71 | K14: =ABS(I14-15.5) | L14: =ABS(J14-14.5) | M14: =MAX(ABS(I14-I13),ABS(J14-J13)) | N14: =1-MAX(K14,L14)/15.5
A15: 9 | B15: ='DP-VI'!D17 | C15: ='DP-VI'!G17 | D15: =ABS(B15-15.5) | E15: =ABS(C15-14.5) | F15: =MAX(ABS(B15-B14),ABS(C15-C14)) | G15: =1-MAX(D15,E15)/15.5 | I15: ='DP-VI'!D72 | J15: ='DP-VI'!G72 | K15: =ABS(I15-15.5) | L15: =ABS(J15-14.5) | M15: =MAX(ABS(I15-I14),ABS(J15-J14)) | N15: =1-MAX(K15,L15)/15.5
A16: 10 | B16: ='DP-VI'!D18 | C16: ='DP-VI'!G18 | D16: =ABS(B16-15.5) | E16: =ABS(C16-14.5) | F16: =MAX(ABS(B16-B15),ABS(C16-C15)) | G16: =1-MAX(D16,E16)/15.5 | I16: ='DP-VI'!D73 | J16: ='DP-VI'!G73 | K16: =ABS(I16-15.5) | L16: =ABS(J16-14.5) | M16: =MAX(ABS(I16-I15),ABS(J16-J15)) | N16: =1-MAX(K16,L16)/15.5
A17: 11 | B17: ='DP-VI'!D19 | C17: ='DP-VI'!G19 | D17: =ABS(B17-15.5) | E17: =ABS(C17-14.5) | F17: =MAX(ABS(B17-B16),ABS(C17-C16)) | G17: =1-MAX(D17,E17)/15.5 | I17: ='DP-VI'!D74 | J17: ='DP-VI'!G74 | K17: =ABS(I17-15.5) | L17: =ABS(J17-14.5) | M17: =MAX(ABS(I17-I16),ABS(J17-J16)) | N17: =1-MAX(K17,L17)/15.5
A18: 12 | B18: ='DP-VI'!D20 | C18: ='DP-VI'!G20 | D18: =ABS(B18-15.5) | E18: =ABS(C18-14.5) | F18: =MAX(ABS(B18-B17),ABS(C18-C17)) | G18: =1-MAX(D18,E18)/15.5 | I18: ='DP-VI'!D75 | J18: ='DP-VI'!G75 | K18: =ABS(I18-15.5) | L18: =ABS(J18-14.5) | M18: =MAX(ABS(I18-I17),ABS(J18-J17)) | N18: =1-MAX(K18,L18)/15.5
... A56: 50 | B56: ='DP-VI'!D58 | C56: ='DP-VI'!G58 | D56: =ABS(B56-15.5) | E56: =ABS(C56-14.5) | F56: =MAX(ABS(B56-B55),ABS(C56-C55)) | G56: =1-MAX(D56,E56)/15.5 | I56: ='DP-VI'!D113 | J56: ='DP-VI'!G113 | K56: =ABS(I56-15.5) | L56: =ABS(J56-14.5) | M56: =MAX(ABS(I56-I55),ABS(J56-J55)) | N56: =1-MAX(K56,L56)/15.5
A58: Convergence Summary
A59: Metric | B59: Synchronous | C59: In-Place
A60: Final V*(Cool) | B60: =B56 | C60: =I56
A61: Final V*(Warm) | B61: =C56 | C61: =J56
A62: Analytical V*(Cool) | B62: 15.5 | C62: 15.5
A63: Analytical V*(Warm) | B63: 14.5 | C63: 14.5
A64: Final |error| | B64: =MAX(D56,E56) | C64: =MAX(K56,L56)
A65: Final % converged | B65: =G56 | C65: =N56
A66: Final |DV| | B66: =F56 | C66: =M56
A67: Contraction |DV_k|/|DV_{k-1}| at k=10 | B67: =F16/F15 | C67: =M16/M15
A68: Expected ratio (gamma) | B68: 0.9 | C68: 0.9
A70: Convergence Speed (first k where |DV| < threshold)
A71: Threshold | B71: Sync k | C71: InPlace k | D71: InPlace faster by
A72: 1 | B72: =IFERROR(SUMPRODUCT((F7:F56>=1.0)*1)+1,">50") | C72: =IFERROR(SUMPRODUCT((M7:M56>=1.0)*1)+1,">50") | D72: =IF(AND(ISNUMBER(B72),ISNUMBER(C72)),B72-C72,"n/a")
A73: 0.1 | B73: =IFERROR(SUMPRODUCT((F7:F56>=0.1)*1)+1,">50") | C73: =IFERROR(SUMPRODUCT((M7:M56>=0.1)*1)+1,">50") | D73: =IF(AND(ISNUMBER(B73),ISNUMBER(C73)),B73-C73,"n/a")
A74: 0.01 | B74: =IFERROR(SUMPRODUCT((F7:F56>=0.01)*1)+1,">50") | C74: =IFERROR(SUMPRODUCT((M7:M56>=0.01)*1)+1,">50") | D74: =IF(AND(ISNUMBER(B74),ISNUMBER(C74)),B74-C74,"n/a")
A75: 0.001 | B75: =IFERROR(SUMPRODUCT((F7:F56>=0.001)*1)+1,">50") | C75: =IFERROR(SUMPRODUCT((M7:M56>=0.001)*1)+1,">50") | D75: =IF(AND(ISNUMBER(B75),ISNUMBER(C75)),B75-C75,"n/a")
A76: 0.0001 | B76: =IFERROR(SUMPRODUCT((F7:F56>=0.0001)*1)+1,">50") | C76: =IFERROR(SUMPRODUCT((M7:M56>=0.0001)*1)+1,">50") | D76: =IF(AND(ISNUMBER(B76),ISNUMBER(C76)),B76-C76,"n/a")

Sheet Analytical
A1: Analytical Solution: Solving the Bellman Optimality Equation for V* and Q*
A3: Step 1: The Bellman Optimality Equation
A4: V*(s) = max_a SUM_{s'} P(s'|s,a) * [ R(s,a,s') + gamma * V*(s') ]
A5: This is a SYSTEM of simultaneous equations. V*(s) on the left and V*(s') on the right are the SAME solution.
A6: It is NOT an iterative update — it describes the fixed point that DP converges TO.
A8: Step 2: Expand Q*(s,a) = SUM P(s'|s,a) * [R + gamma*V*(s')] for each (s,a)
A9: (s, a) | B9: Expansion | C9: Simplified
A10: (Cool, Slow) | B10: P(C|C,S)*[R(C,S,C)+g*V*(C)] + P(W|C,S)*[R(C,S,W)+g*V*(W)] | C10: 0.5*(1+0.9*V*(C)) + 0.5*(1+0.9*V*(W))
A11: (Cool, Fast) | B11: P(C|C,F)*[R(C,F,C)+g*V*(C)] + P(W|C,F)*[R(C,F,W)+g*V*(W)] | C11: 0.5*(2+0.9*V*(C)) + 0.5*(2+0.9*V*(W))
A12: (Warm, Slow) | B12: P(C|W,S)*[R(W,S,C)+g*V*(C)] + P(W|W,S)*[R(W,S,W)+g*V*(W)] | C12: 0.5*(1+0.9*V*(C)) + 0.5*(1+0.9*V*(W))
A13: (Warm, Fast) | B13: P(OH|W,F)*[R(W,F,OH)+g*V*(OH)] | C13: 1*(-10+0.9*0) = -10
A15: Step 3: Why This Is a SYSTEM of Equations (Circular Dependency)
A16: In TRUE recursion, you start from a base case (leaf) and work backward — each unknown depends only on ALREADY-KNOWN values.
A17: Here, the Bellman equation is CIRCULAR: V*(Cool) needs V*(Warm), and V*(Warm) needs V*(Cool). Neither can be solved first.
A19: Trace the dependency chain:
A20: # | B20: To compute... | C20: We need... | D20: Which requires... | E20: Problem
A21: 1 | B21: V*(Cool) = max Q*(Cool,a) | C21: Q*(Cool,Fast) = 0.5*(2+0.9*V*(C)) + 0.5*(2+0.9*V*(W)) | D21: V*(Cool) AND V*(Warm) | E21: V*(Warm) is UNKNOWN
A22: 2 | B22: V*(Warm) = max Q*(Warm,a) | C22: Q*(Warm,Slow) = 0.5*(1+0.9*V*(C)) + 0.5*(1+0.9*V*(W)) | D22: V*(Cool) AND V*(Warm) | E22: V*(Cool) is UNKNOWN
A23: 3 | B23: Attempt: solve V*(Cool) first? | C23: Stuck — need V*(Warm) which needs V*(Cool) | D23: CIRCULAR: Cool -> Warm -> Cool -> ... | E23: No ordering exists!
A24: 4 | B24: Attempt: solve V*(Warm) first? | C24: Stuck — need V*(Cool) which needs V*(Warm) | D24: CIRCULAR: Warm -> Cool -> Warm -> ... | E24: Same deadlock!
A26: The ROOT CAUSE: Cycles in the transition graph
A27: Cool --[Fast/Slow]--> Cool or Warm. Warm --[Slow]--> Cool or Warm. This creates a CYCLE: Cool <-> Warm.
A28: Cycles mean mutual dependency. The value of being in Cool depends on what happens in Warm, and vice versa.
A30: Contrast: When IS it simple recursion? (no cycles)
A31: Scenario | B31: Dependency | C31: Solvable by recursion?
A32: Q*(Warm, Fast) = -10 | B32: Only depends on V*(OH) = 0 (terminal, KNOWN) | C32: YES — base case, no unknowns
A33: A -> B -> C -> Terminal (no cycles) | B33: V*(C) needs terminal only, V*(B) needs V*(C), V*(A) needs V*(B) | C33: YES — solve backward from terminal
A34: Cool <-> Warm (our problem!) | B34: V*(Cool) needs V*(Warm), V*(Warm) needs V*(Cool) | C34: NO — must solve simultaneously
A35: N states all connected to each other | B35: Every V*(s) depends on every other V*(s') | C35: NO — N equations in N unknowns
A37: Three ways to handle the circular dependency:
A38: 1. ALGEBRA (this sheet): Introduce variable x, substitute, solve the resulting equation. Works for small MDPs.
A39: 2. LINEAR ALGEBRA: Write as matrix equation V = R + gamma*P*V, solve (I - gamma*P)*V = R. Works for any size.
A40: 3. ITERATIVE (DP): Start with V=0, repeatedly apply Bellman update. Converges to the fixed point (see DP-VI sheet).
A42: SUMMARY: It's called a 'system' because V*(Cool) and V*(Warm) are coupled unknowns that must be solved TOGETHER, not one after the other.
A44: Step 4: Key Observations (before solving)
A45: Q*(Cool,Slow) = Q*(Warm,Slow) — same formula because both have 0.5/0.5 to Cool/Warm with R=1
A46: Q*(Cool,Fast) = Q*(Cool,Slow) + 1 — Fast just adds +1 more reward per transition (2 vs 1)
A47: Q*(Warm,Fast) = -10 — no unknowns, Warm+Fast always goes to terminal Overheated
A48: Since Q*(Cool,Fast) > Q*(Cool,Slow) always: V*(Cool) = Q*(Cool,Fast) — optimal action at Cool is Fast
A49: Since Q*(Warm,Slow) >> Q*(Warm,Fast)=-10: V*(Warm) = Q*(Warm,Slow) — optimal action at Warm is Slow
...

Sheet Summary
A1: V, V*, Q, Q* — Complete Summary + Policy Iteration
A2: All values are formulas referencing DP-Eval / DP-VI converged results, or computing Q from V via Bellman.
A4: Section 1: State Value Functions
A5: State | B5: V^cautious ✱ | C5: V^optimal ✱ | D5: V^aggressive ✱ | E5: V^worst ✱ | F5: V* ✱
A6: Cool | B6: ='DP-Eval'!B59 | C6: ='DP-Eval'!B116 | D6: ='DP-Eval'!B173 | E6: ='DP-Eval'!B230 | F6: ='DP-VI'!D58
A7: Warm | B7: ='DP-Eval'!C59 | C7: ='DP-Eval'!C116 | D7: ='DP-Eval'!C173 | E7: ='DP-Eval'!C230 | F7: ='DP-VI'!G58
A8: Overheated | B8: 0 | C8: 0 | D8: 0 | E8: 0 | F8: 0
A10: Section 2a: Q^cautious(s,a)
A11: Q(s,a) = Σ P(s'|s,a)·[R(s,a,s') + γ·cautious(s')]
A12: (s, a) | B12: Q^cautious(s,a) ✱
A13: (Cool, Slow) | B13: =0.5*(1+0.9*B6)+0.5*(1+0.9*B7)
A14: (Cool, Fast) | B14: =0.5*(2+0.9*B6)+0.5*(2+0.9*B7)
A15: (Warm, Slow) | B15: =0.5*(1+0.9*B6)+0.5*(1+0.9*B7)
A16: (Warm, Fast) | B16: =1*(-10+0.9*0)
A18: Section 2b: Q^optimal(s,a)
A19: Q(s,a) = Σ P(s'|s,a)·[R(s,a,s') + γ·optimal(s')]
A20: (s, a) | B20: Q^optimal(s,a) ✱
A21: (Cool, Slow) | B21: =0.5*(1+0.9*C6)+0.5*(1+0.9*C7)
A22: (Cool, Fast) | B22: =0.5*(2+0.9*C6)+0.5*(2+0.9*C7)
A23: (Warm, Slow) | B23: =0.5*(1+0.9*C6)+0.5*(1+0.9*C7)
A24: (Warm, Fast) | B24: =1*(-10+0.9*0)
A26: Section 2c: Q^aggressive(s,a)
A27: Q(s,a) = Σ P(s'|s,a)·[R(s,a,s') + γ·aggressive(s')]
A28: (s, a) | B28: Q^aggressive(s,a) ✱
A29: (Cool, Slow) | B29: =0.5*(1+0.9*D6)+0.5*(1+0.9*D7)
A30: (Cool, Fast) | B30: =0.5*(2+0.9*D6)+0.5*(2+0.9*D7)
A31: (Warm, Slow) | B31: =0.5*(1+0.9*D6)+0.5*(1+0.9*D7)
A32: (Warm, Fast) | B32: =1*(-10+0.9*0)
A34: Section 2d: Q^worst(s,a)
A35: Q(s,a) = Σ P(s'|s,a)·[R(s,a,s') + γ·worst(s')]
A36: (s, a) | B36: Q^worst(s,a) ✱
A37: (Cool, Slow) | B37: =0.5*(1+0.9*E6)+0.5*(1+0.9*E7)
A38: (Cool, Fast) | B38: =0.5*(2+0.9*E6)+0.5*(2+0.9*E7)
A39: (Warm, Slow) | B39: =0.5*(1+0.9*E6)+0.5*(1+0.9*E7)
A40: (Warm, Fast) | B40: =1*(-10+0.9*0)
A42: Section 2e: Q*(s,a) from V*
A43: Q(s,a) = Σ P(s'|s,a)·[R(s,a,s') + γ·*(s')]
A44: (s, a) | B44: Q^*(s,a) ✱
A45: (Cool, Slow) | B45: =0.5*(1+0.9*F6)+0.5*(1+0.9*F7)
A46: (Cool, Fast) | B46: =0.5*(2+0.9*F6)+0.5*(2+0.9*F7)
...

Sheet MC-Episodes
A1: Monte Carlo — Episodes with Return-to-Go
A2: NOTE: t = time step within an episode (one single transition s→s'). Unlike DP's k (full sweep over all states), t advances one step at a time.
A3: F=0.9^A (discount). G_T=E_T (last step r). G_t=E_t+0.9·G_{t+1} (backward recursion).
A5: Episode 1
A6: Step (t) | B6: s | C6: a | D6: s' | E6: r | F6: γ^t ✱ | G6: G_t ✱
A7: 0 | B7: Cool | C7: Fast | D7: Cool | E7: 2 | F7: =0.9^A7 | G7: =E7+0.9*G8
A8: 1 | B8: Cool | C8: Fast | D8: Cool | E8: 2 | F8: =0.9^A8 | G8: =E8+0.9*G9
A9: 2 | B9: Cool | C9: Fast | D9: Cool | E9: 2 | F9: =0.9^A9 | G9: =E9+0.9*G10
A10: 3 | B10: Cool | C10: Fast | D10: Cool | E10: 2 | F10: =0.9^A10 | G10: =E10+0.9*G11
A11: 4 | B11: Cool | C11: Fast | D11: Cool | E11: 2 | F11: =0.9^A11 | G11: =E11+0.9*G12
A12: 5 | B12: Cool | C12: Fast | D12: Cool | E12: 2 | F12: =0.9^A12 | G12: =E12+0.9*G13
A13: 6 | B13: Cool | C13: Fast | D13: Cool | E13: 2 | F13: =0.9^A13 | G13: =E13+0.9*G14
A14: 7 | B14: Cool | C14: Fast | D14: Warm | E14: 2 | F14: =0.9^A14 | G14: =E14+0.9*G15
A15: 8 | B15: Warm | C15: Slow | D15: Warm | E15: 1 | F15: =0.9^A15 | G15: =E15+0.9*G16
A16: 9 | B16: Warm | C16: Slow | D16: Cool | E16: 1 | F16: =0.9^A16 | G16: =E16+0.9*G17
A17: 10 | B17: Cool | C17: Fast | D17: Cool | E17: 2 | F17: =0.9^A17 | G17: =E17+0.9*G18
A18: 11 | B18: Cool | C18: Fast | D18: Warm | E18: 2 | F18: =0.9^A18 | G18: =E18+0.9*G19
... A25: 18 | B25: Cool | C25: Slow | D25: Warm | E25: 1 | F25: =0.9^A25 | G25: =E25+0.9*G26
A26: 19 | B26: Warm | C26: Slow | D26: Warm | E26: 1 | F26: =0.9^A26 | G26: =E26
A27: G₀ = | B27: =G7
A29: Episode 2
A30: Step (t) | B30: s | C30: a | D30: s' | E30: r | F30: γ^t ✱ | G30: G_t ✱
A31: 0 | B31: Cool | C31: Fast | D31: Warm | E31: 2 | F31: =0.9^A31 | G31: =E31+0.9*G32
A32: 1 | B32: Warm | C32: Slow | D32: Cool | E32: 1 | F32: =0.9^A32 | G32: =E32+0.9*G33
A33: 2 | B33: Cool | C33: Fast | D33: Cool | E33: 2 | F33: =0.9^A33 | G33: =E33+0.9*G34
A34: 3 | B34: Cool | C34: Fast | D34: Cool | E34: 2 | F34: =0.9^A34 | G34: =E34+0.9*G35
A35: 4 | B35: Cool | C35: Fast | D35: Cool | E35: 2 | F35: =0.9^A35 | G35: =E35+0.9*G36
A36: 5 | B36: Cool | C36: Fast | D36: Warm | E36: 2 | F36: =0.9^A36 | G36: =E36+0.9*G37
A37: 6 | B37: Warm | C37: Slow | D37: Warm | E37: 1 | F37: =0.9^A37 | G37: =E37+0.9*G38
A38: 7 | B38: Warm | C38: Slow | D38: Warm | E38: 1 | F38: =0.9^A38 | G38: =E38+0.9*G39
A39: 8 | B39: Warm | C39: Slow | D39: Warm | E39: 1 | F39: =0.9^A39 | G39: =E39+0.9*G40
A40: 9 | B40: Warm | C40: Slow | D40: Cool | E40: 1 | F40: =0.9^A40 | G40: =E40+0.9*G41
A41: 10 | B41: Cool | C41: Fast | D41: Cool | E41: 2 | F41: =0.9^A41 | G41: =E41+0.9*G42
A42: 11 | B42: Cool | C42: Fast | D42: Cool | E42: 2 | F42: =0.9^A42 | G42: =E42+0.9*G43
... A49: 18 | B49: Cool | C49: Slow | D49: Warm | E49: 1 | F49: =0.9^A49 | G49: =E49+0.9*G50
A50: 19 | B50: Warm | C50: Slow | D50: Warm | E50: 1 | F50: =0.9^A50 | G50: =E50
A51: G₀ = | B51: =G31
A53: Episode 3
A54: Step (t) | B54: s | C54: a | D54: s' | E54: r | F54: γ^t ✱ | G54: G_t ✱
A55: 0 | B55: Cool | C55: Fast | D55: Warm | E55: 2 | F55: =0.9^A55 | G55: =E55+0.9*G56
...

Sheet MC-VQ
A1: Monte Carlo — First-Visit V(s) and Q(s,a) Estimation
A2: Each cell = G_t of the first visit in that episode (cross-sheet ref). V/Q = AVERAGE of those returns.
A4: V^MC(s) = average of first-visit G_t per state
A5: State | B5: Ep1 G_t ✱ | C5: Ep2 G_t ✱ | D5: Ep3 G_t ✱ | E5: Ep4 G_t ✱ | F5: Ep5 G_t ✱ | G5: V^MC(s) ✱
A6: Cool | B6: ='MC-Episodes'!G7 | C6: ='MC-Episodes'!G31 | D6: ='MC-Episodes'!G55 | E6: ='MC-Episodes'!G79 | F6: ='MC-Episodes'!G97 | G6: =AVERAGE(B6:F6)
A7: Warm | B7: ='MC-Episodes'!G15 | C7: ='MC-Episodes'!G32 | D7: ='MC-Episodes'!G56 | E7: ='MC-Episodes'!G81 | F7: ='MC-Episodes'!G98 | G7: =AVERAGE(B7:F7)
A8: Overheated | B8: 0 | G8: 0
A10: Q^MC(s,a) = average of first-visit G_t per (s,a)
A11: (s, a) | B11: Ep1 G_t ✱ | C11: Ep2 G_t ✱ | D11: Ep3 G_t ✱ | E11: Ep4 G_t ✱ | F11: Ep5 G_t ✱ | G11: Q^MC(s,a) ✱
A12: (Cool, Slow) | B12: ='MC-Episodes'!G20 | C12: ='MC-Episodes'!G49 | D12: ='MC-Episodes'!G73 | G12: =AVERAGE(B12:F12)
A13: (Cool, Fast) | B13: ='MC-Episodes'!G7 | C13: ='MC-Episodes'!G31 | D13: ='MC-Episodes'!G55 | E13: ='MC-Episodes'!G79 | F13: ='MC-Episodes'!G97 | G13: =AVERAGE(B13:F13)
A14: (Warm, Slow) | B14: ='MC-Episodes'!G15 | C14: ='MC-Episodes'!G32 | D14: ='MC-Episodes'!G56 | E14: ='MC-Episodes'!G81 | G14: =AVERAGE(B14:F14)
A15: (Warm, Fast) | D15: ='MC-Episodes'!G74 | E15: ='MC-Episodes'!G92 | F15: ='MC-Episodes'!G98 | G15: =AVERAGE(B15:F15)
A17: Greedy Policy from Q^MC: π(s) = argmax_a Q^MC(s,a)
A18: State | B18: π(s) ✱ | C18: Q^MC(s,π(s)) ✱
A19: Cool | B19: =IF(G13>=G12,"Fast","Slow") | C19: =MAX(G12,G13)
A20: Warm | B20: =IF(G15>=G14,"Fast","Slow") | C20: =MAX(G14,G15)

Sheet TD0
A1: TD(0) — Step-by-Step V(s) Updates
A2: NOTE: Each row = one time step t (a single transition s→s'), NOT a full sweep. TD updates V(s) after every step, unlike DP which sweeps all states per iteration k.
A3: V(s) ← V(s) + α·[r + γ·V(s') − V(s)]. α=0.1, γ=0.9. L,M track V(Cool),V(Warm) after each step.
A5: Step | B5: Ep | C5: s | D5: a | E5: r | F5: s' | G5: V(s) bef ✱ | H5: V(s') ✱ | I5: Target ✱ | J5: Error ✱ | K5: V(s) aft ✱ | L5: V(Cool) ✱ | M5: V(Warm) ✱
A6: init | B6: init | C6: init | D6: init | E6: init | F6: init | L6: 0 | M6: 0
A7: 1 | B7: 1 | C7: Cool | D7: Fast | E7: 2 | F7: Cool | G7: =IF(C7="Cool",L6,M6) | H7: =IF(F7="Overheated",0,IF(F7="Cool",L6,M6)) | I7: =E7+0.9*H7 | J7: =I7-G7 | K7: =G7+0.1*J7 | L7: =IF(C7="Cool",K7,L6) | M7: =IF(C7="Warm",K7,M6)
A8: 2 | B8: 1 | C8: Cool | D8: Fast | E8: 2 | F8: Cool | G8: =IF(C8="Cool",L7,M7) | H8: =IF(F8="Overheated",0,IF(F8="Cool",L7,M7)) | I8: =E8+0.9*H8 | J8: =I8-G8 | K8: =G8+0.1*J8 | L8: =IF(C8="Cool",K8,L7) | M8: =IF(C8="Warm",K8,M7)
A9: 3 | B9: 1 | C9: Cool | D9: Fast | E9: 2 | F9: Cool | G9: =IF(C9="Cool",L8,M8) | H9: =IF(F9="Overheated",0,IF(F9="Cool",L8,M8)) | I9: =E9+0.9*H9 | J9: =I9-G9 | K9: =G9+0.1*J9 | L9: =IF(C9="Cool",K9,L8) | M9: =IF(C9="Warm",K9,M8)
A10: 4 | B10: 1 | C10: Cool | D10: Fast | E10: 2 | F10: Cool | G10: =IF(C10="Cool",L9,M9) | H10: =IF(F10="Overheated",0,IF(F10="Cool",L9,M9)) | I10: =E10+0.9*H10 | J10: =I10-G10 | K10: =G10+0.1*J10 | L10: =IF(C10="Cool",K10,L9) | M10: =IF(C10="Warm",K10,M9)
A11: 5 | B11: 1 | C11: Cool | D11: Fast | E11: 2 | F11: Cool | G11: =IF(C11="Cool",L10,M10) | H11: =IF(F11="Overheated",0,IF(F11="Cool",L10,M10)) | I11: =E11+0.9*H11 | J11: =I11-G11 | K11: =G11+0.1*J11 | L11: =IF(C11="Cool",K11,L10) | M11: =IF(C11="Warm",K11,M10)
A12: 6 | B12: 1 | C12: Cool | D12: Fast | E12: 2 | F12: Cool | G12: =IF(C12="Cool",L11,M11) | H12: =IF(F12="Overheated",0,IF(F12="Cool",L11,M11)) | I12: =E12+0.9*H12 | J12: =I12-G12 | K12: =G12+0.1*J12 | L12: =IF(C12="Cool",K12,L11) | M12: =IF(C12="Warm",K12,M11)
A13: 7 | B13: 1 | C13: Cool | D13: Fast | E13: 2 | F13: Cool | G13: =IF(C13="Cool",L12,M12) | H13: =IF(F13="Overheated",0,IF(F13="Cool",L12,M12)) | I13: =E13+0.9*H13 | J13: =I13-G13 | K13: =G13+0.1*J13 | L13: =IF(C13="Cool",K13,L12) | M13: =IF(C13="Warm",K13,M12)
A14: 8 | B14: 1 | C14: Cool | D14: Fast | E14: 2 | F14: Warm | G14: =IF(C14="Cool",L13,M13) | H14: =IF(F14="Overheated",0,IF(F14="Cool",L13,M13)) | I14: =E14+0.9*H14 | J14: =I14-G14 | K14: =G14+0.1*J14 | L14: =IF(C14="Cool",K14,L13) | M14: =IF(C14="Warm",K14,M13)
A15: 9 | B15: 1 | C15: Warm | D15: Slow | E15: 1 | F15: Warm | G15: =IF(C15="Cool",L14,M14) | H15: =IF(F15="Overheated",0,IF(F15="Cool",L14,M14)) | I15: =E15+0.9*H15 | J15: =I15-G15 | K15: =G15+0.1*J15 | L15: =IF(C15="Cool",K15,L14) | M15: =IF(C15="Warm",K15,M14)
A16: 10 | B16: 1 | C16: Warm | D16: Slow | E16: 1 | F16: Cool | G16: =IF(C16="Cool",L15,M15) | H16: =IF(F16="Overheated",0,IF(F16="Cool",L15,M15)) | I16: =E16+0.9*H16 | J16: =I16-G16 | K16: =G16+0.1*J16 | L16: =IF(C16="Cool",K16,L15) | M16: =IF(C16="Warm",K16,M15)
A17: 11 | B17: 1 | C17: Cool | D17: Fast | E17: 2 | F17: Cool | G17: =IF(C17="Cool",L16,M16) | H17: =IF(F17="Overheated",0,IF(F17="Cool",L16,M16)) | I17: =E17+0.9*H17 | J17: =I17-G17 | K17: =G17+0.1*J17 | L17: =IF(C17="Cool",K17,L16) | M17: =IF(C17="Warm",K17,M16)
A18: 12 | B18: 1 | C18: Cool | D18: Fast | E18: 2 | F18: Warm | G18: =IF(C18="Cool",L17,M17) | H18: =IF(F18="Overheated",0,IF(F18="Cool",L17,M17)) | I18: =E18+0.9*H18 | J18: =I18-G18 | K18: =G18+0.1*J18 | L18: =IF(C18="Cool",K18,L17) | M18: =IF(C18="Warm",K18,M17)
... A82: 76 | B82: 5 | C82: Warm | D82: Fast | E82: -10 | F82: Overheated | G82: =IF(C82="Cool",L81,M81) | H82: =IF(F82="Overheated",0,IF(F82="Cool",L81,M81)) | I82: =E82+0.9*H82 | J82: =I82-G82 | K82: =G82+0.1*J82 | L82: =IF(C82="Cool",K82,L81) | M82: =IF(C82="Warm",K82,M81)
A84: Final V^TD(0)(s) after all episodes
A85: State | B85: V(s) ✱
A86: Cool | B86: =L82
A87: Warm | B87: =M82
A88: Overheated | B88: 0

Sheet SARSA
A1: SARSA — On-Policy Q(s,a) Updates
A2: NOTE: Each row = one time step t (a single transition s,a→r,s',a'), NOT a full sweep. SARSA updates Q(s,a) after every step using the ACTUAL next action a'.
A3: Q(s,a) ← Q(s,a) + α·[r + γ·Q(s',a') − Q(s,a)]. α=0.1, γ=0.9. M-P track the full Q-table.
A5: Step | B5: Ep | C5: s | D5: a | E5: r | F5: s' | G5: a' | H5: Q(s,a) bef ✱ | I5: Q(s',a') ✱ | J5: Target ✱ | K5: Error ✱ | L5: Q aft ✱ | M5: Q(C,S) ✱ | N5: Q(C,F) ✱ | O5: Q(W,S) ✱ | P5: Q(W,F) ✱
A6: init | B6: init | C6: init | D6: init | E6: init | F6: init | G6: init | M6: 0 | N6: 0 | O6: 0 | P6: 0
A7: 1 | B7: 1 | C7: Cool | D7: Fast | E7: 2 | F7: Cool | G7: Fast | H7: =IF(AND(C7="Cool",D7="Slow"),M6,IF(AND(C7="Cool",D7="Fast"),N6,IF(AND(C7="Warm",D7="Slow"),O6,P6))) | I7: =IF(F7="Overheated",0,IF(AND(F7="Cool",G7="Slow"),M6,IF(AND(F7="Cool",G7="Fast"),N6,IF(AND(F7="Warm",G7="Slow"),O6,P6)))) | J7: =E7+0.9*I7 | K7: =J7-H7 | L7: =H7+0.1*K7 | M7: =IF(AND(C7="Cool",D7="Slow"),L7,M6) | N7: =IF(AND(C7="Cool",D7="Fast"),L7,N6) | O7: =IF(AND(C7="Warm",D7="Slow"),L7,O6) | P7: =IF(AND(C7="Warm",D7="Fast"),L7,P6)
A8: 2 | B8: 1 | C8: Cool | D8: Fast | E8: 2 | F8: Cool | G8: Fast | H8: =IF(AND(C8="Cool",D8="Slow"),M7,IF(AND(C8="Cool",D8="Fast"),N7,IF(AND(C8="Warm",D8="Slow"),O7,P7))) | I8: =IF(F8="Overheated",0,IF(AND(F8="Cool",G8="Slow"),M7,IF(AND(F8="Cool",G8="Fast"),N7,IF(AND(F8="Warm",G8="Slow"),O7,P7)))) | J8: =E8+0.9*I8 | K8: =J8-H8 | L8: =H8+0.1*K8 | M8: =IF(AND(C8="Cool",D8="Slow"),L8,M7) | N8: =IF(AND(C8="Cool",D8="Fast"),L8,N7) | O8: =IF(AND(C8="Warm",D8="Slow"),L8,O7) | P8: =IF(AND(C8="Warm",D8="Fast"),L8,P7)
A9: 3 | B9: 1 | C9: Cool | D9: Fast | E9: 2 | F9: Cool | G9: Fast | H9: =IF(AND(C9="Cool",D9="Slow"),M8,IF(AND(C9="Cool",D9="Fast"),N8,IF(AND(C9="Warm",D9="Slow"),O8,P8))) | I9: =IF(F9="Overheated",0,IF(AND(F9="Cool",G9="Slow"),M8,IF(AND(F9="Cool",G9="Fast"),N8,IF(AND(F9="Warm",G9="Slow"),O8,P8)))) | J9: =E9+0.9*I9 | K9: =J9-H9 | L9: =H9+0.1*K9 | M9: =IF(AND(C9="Cool",D9="Slow"),L9,M8) | N9: =IF(AND(C9="Cool",D9="Fast"),L9,N8) | O9: =IF(AND(C9="Warm",D9="Slow"),L9,O8) | P9: =IF(AND(C9="Warm",D9="Fast"),L9,P8)
A10: 4 | B10: 1 | C10: Cool | D10: Fast | E10: 2 | F10: Cool | G10: Fast | H10: =IF(AND(C10="Cool",D10="Slow"),M9,IF(AND(C10="Cool",D10="Fast"),N9,IF(AND(C10="Warm",D10="Slow"),O9,P9))) | I10: =IF(F10="Overheated",0,IF(AND(F10="Cool",G10="Slow"),M9,IF(AND(F10="Cool",G10="Fast"),N9,IF(AND(F10="Warm",G10="Slow"),O9,P9)))) | J10: =E10+0.9*I10 | K10: =J10-H10 | L10: =H10+0.1*K10 | M10: =IF(AND(C10="Cool",D10="Slow"),L10,M9) | N10: =IF(AND(C10="Cool",D10="Fast"),L10,N9) | O10: =IF(AND(C10="Warm",D10="Slow"),L10,O9) | P10: =IF(AND(C10="Warm",D10="Fast"),L10,P9)
A11: 5 | B11: 1 | C11: Cool | D11: Fast | E11: 2 | F11: Cool | G11: Fast | H11: =IF(AND(C11="Cool",D11="Slow"),M10,IF(AND(C11="Cool",D11="Fast"),N10,IF(AND(C11="Warm",D11="Slow"),O10,P10))) | I11: =IF(F11="Overheated",0,IF(AND(F11="Cool",G11="Slow"),M10,IF(AND(F11="Cool",G11="Fast"),N10,IF(AND(F11="Warm",G11="Slow"),O10,P10)))) | J11: =E11+0.9*I11 | K11: =J11-H11 | L11: =H11+0.1*K11 | M11: =IF(AND(C11="Cool",D11="Slow"),L11,M10) | N11: =IF(AND(C11="Cool",D11="Fast"),L11,N10) | O11: =IF(AND(C11="Warm",D11="Slow"),L11,O10) | P11: =IF(AND(C11="Warm",D11="Fast"),L11,P10)
A12: 6 | B12: 1 | C12: Cool | D12: Fast | E12: 2 | F12: Cool | G12: Fast | H12: =IF(AND(C12="Cool",D12="Slow"),M11,IF(AND(C12="Cool",D12="Fast"),N11,IF(AND(C12="Warm",D12="Slow"),O11,P11))) | I12: =IF(F12="Overheated",0,IF(AND(F12="Cool",G12="Slow"),M11,IF(AND(F12="Cool",G12="Fast"),N11,IF(AND(F12="Warm",G12="Slow"),O11,P11)))) | J12: =E12+0.9*I12 | K12: =J12-H12 | L12: =H12+0.1*K12 | M12: =IF(AND(C12="Cool",D12="Slow"),L12,M11) | N12: =IF(AND(C12="Cool",D12="Fast"),L12,N11) | O12: =IF(AND(C12="Warm",D12="Slow"),L12,O11) | P12: =IF(AND(C12="Warm",D12="Fast"),L12,P11)
A13: 7 | B13: 1 | C13: Cool | D13: Fast | E13: 2 | F13: Cool | G13: Fast | H13: =IF(AND(C13="Cool",D13="Slow"),M12,IF(AND(C13="Cool",D13="Fast"),N12,IF(AND(C13="Warm",D13="Slow"),O12,P12))) | I13: =IF(F13="Overheated",0,IF(AND(F13="Cool",G13="Slow"),M12,IF(AND(F13="Cool",G13="Fast"),N12,IF(AND(F13="Warm",G13="Slow"),O12,P12)))) | J13: =E13+0.9*I13 | K13: =J13-H13 | L13: =H13+0.1*K13 | M13: =IF(AND(C13="Cool",D13="Slow"),L13,M12) | N13: =IF(AND(C13="Cool",D13="Fast"),L13,N12) | O13: =IF(AND(C13="Warm",D13="Slow"),L13,O12) | P13: =IF(AND(C13="Warm",D13="Fast"),L13,P12)
A14: 8 | B14: 1 | C14: Cool | D14: Fast | E14: 2 | F14: Warm | G14: Slow | H14: =IF(AND(C14="Cool",D14="Slow"),M13,IF(AND(C14="Cool",D14="Fast"),N13,IF(AND(C14="Warm",D14="Slow"),O13,P13))) | I14: =IF(F14="Overheated",0,IF(AND(F14="Cool",G14="Slow"),M13,IF(AND(F14="Cool",G14="Fast"),N13,IF(AND(F14="Warm",G14="Slow"),O13,P13)))) | J14: =E14+0.9*I14 | K14: =J14-H14 | L14: =H14+0.1*K14 | M14: =IF(AND(C14="Cool",D14="Slow"),L14,M13) | N14: =IF(AND(C14="Cool",D14="Fast"),L14,N13) | O14: =IF(AND(C14="Warm",D14="Slow"),L14,O13) | P14: =IF(AND(C14="Warm",D14="Fast"),L14,P13)
A15: 9 | B15: 1 | C15: Warm | D15: Slow | E15: 1 | F15: Warm | G15: Slow | H15: =IF(AND(C15="Cool",D15="Slow"),M14,IF(AND(C15="Cool",D15="Fast"),N14,IF(AND(C15="Warm",D15="Slow"),O14,P14))) | I15: =IF(F15="Overheated",0,IF(AND(F15="Cool",G15="Slow"),M14,IF(AND(F15="Cool",G15="Fast"),N14,IF(AND(F15="Warm",G15="Slow"),O14,P14)))) | J15: =E15+0.9*I15 | K15: =J15-H15 | L15: =H15+0.1*K15 | M15: =IF(AND(C15="Cool",D15="Slow"),L15,M14) | N15: =IF(AND(C15="Cool",D15="Fast"),L15,N14) | O15: =IF(AND(C15="Warm",D15="Slow"),L15,O14) | P15: =IF(AND(C15="Warm",D15="Fast"),L15,P14)
A16: 10 | B16: 1 | C16: Warm | D16: Slow | E16: 1 | F16: Cool | G16: Fast | H16: =IF(AND(C16="Cool",D16="Slow"),M15,IF(AND(C16="Cool",D16="Fast"),N15,IF(AND(C16="Warm",D16="Slow"),O15,P15))) | I16: =IF(F16="Overheated",0,IF(AND(F16="Cool",G16="Slow"),M15,IF(AND(F16="Cool",G16="Fast"),N15,IF(AND(F16="Warm",G16="Slow"),O15,P15)))) | J16: =E16+0.9*I16 | K16: =J16-H16 | L16: =H16+0.1*K16 | M16: =IF(AND(C16="Cool",D16="Slow"),L16,M15) | N16: =IF(AND(C16="Cool",D16="Fast"),L16,N15) | O16: =IF(AND(C16="Warm",D16="Slow"),L16,O15) | P16: =IF(AND(C16="Warm",D16="Fast"),L16,P15)
A17: 11 | B17: 1 | C17: Cool | D17: Fast | E17: 2 | F17: Cool | G17: Fast | H17: =IF(AND(C17="Cool",D17="Slow"),M16,IF(AND(C17="Cool",D17="Fast"),N16,IF(AND(C17="Warm",D17="Slow"),O16,P16))) | I17: =IF(F17="Overheated",0,IF(AND(F17="Cool",G17="Slow"),M16,IF(AND(F17="Cool",G17="Fast"),N16,IF(AND(F17="Warm",G17="Slow"),O16,P16)))) | J17: =E17+0.9*I17 | K17: =J17-H17 | L17: =H17+0.1*K17 | M17: =IF(AND(C17="Cool",D17="Slow"),L17,M16) | N17: =IF(AND(C17="Cool",D17="Fast"),L17,N16) | O17: =IF(AND(C17="Warm",D17="Slow"),L17,O16) | P17: =IF(AND(C17="Warm",D17="Fast"),L17,P16)
A18: 12 | B18: 1 | C18: Cool | D18: Fast | E18: 2 | F18: Warm | G18: Slow | H18: =IF(AND(C18="Cool",D18="Slow"),M17,IF(AND(C18="Cool",D18="Fast"),N17,IF(AND(C18="Warm",D18="Slow"),O17,P17))) | I18: =IF(F18="Overheated",0,IF(AND(F18="Cool",G18="Slow"),M17,IF(AND(F18="Cool",G18="Fast"),N17,IF(AND(F18="Warm",G18="Slow"),O17,P17)))) | J18: =E18+0.9*I18 | K18: =J18-H18 | L18: =H18+0.1*K18 | M18: =IF(AND(C18="Cool",D18="Slow"),L18,M17) | N18: =IF(AND(C18="Cool",D18="Fast"),L18,N17) | O18: =IF(AND(C18="Warm",D18="Slow"),L18,O17) | P18: =IF(AND(C18="Warm",D18="Fast"),L18,P17)
... A82: 76 | B82: 5 | C82: Warm | D82: Fast | E82: -10 | F82: Overheated | G82: — | H82: =IF(AND(C82="Cool",D82="Slow"),M81,IF(AND(C82="Cool",D82="Fast"),N81,IF(AND(C82="Warm",D82="Slow"),O81,P81))) | I82: =IF(F82="Overheated",0,IF(AND(F82="Cool",G82="Slow"),M81,IF(AND(F82="Cool",G82="Fast"),N81,IF(AND(F82="Warm",G82="Slow"),O81,P81)))) | J82: =E82+0.9*I82 | K82: =J82-H82 | L82: =H82+0.1*K82 | M82: =IF(AND(C82="Cool",D82="Slow"),L82,M81) | N82: =IF(AND(C82="Cool",D82="Fast"),L82,N81) | O82: =IF(AND(C82="Warm",D82="Slow"),L82,O81) | P82: =IF(AND(C82="Warm",D82="Fast"),L82,P81)
A84: Final Q^SARSA(s,a)
A85: State\Action | B85: Slow ✱ | C85: Fast ✱
A86: Cool | B86: =M82 | C86: =N82
A87: Warm | B87: =O82 | C87: =P82
A88: Overheated | B88: 0 | C88: 0
A90: Greedy Policy from Q^SARSA
A91: State | B91: π(s) ✱
A92: Cool | B92: =IF(C86>=B86,"Fast","Slow")
A93: Warm | B93: =IF(C87>=B87,"Fast","Slow")

Sheet QLearning
A1: Q-Learning — Off-Policy Q*(s,a) Updates
A2: NOTE: Each row = one time step t (a single transition s,a→r,s'). Q-Learning uses max_{a'} Q(s',a') — the BEST possible action, not the one actually taken (off-policy).
A3: Q(s,a) ← Q(s,a) + α·[r + γ·max_{a'} Q(s',a') − Q(s,a)]. α=0.1, γ=0.9. L-O track Q-table.
A5: Step | B5: Ep | C5: s | D5: a | E5: r | F5: s' | G5: Q(s,a) bef ✱ | H5: max Q(s',·) ✱ | I5: Target ✱ | J5: Error ✱ | K5: Q aft ✱ | L5: Q(C,S) ✱ | M5: Q(C,F) ✱ | N5: Q(W,S) ✱ | O5: Q(W,F) ✱
A6: init | B6: init | C6: init | D6: init | E6: init | F6: init | L6: 0 | M6: 0 | N6: 0 | O6: 0
A7: 1 | B7: 1 | C7: Cool | D7: Fast | E7: 2 | F7: Cool | G7: =IF(AND(C7="Cool",D7="Slow"),L6,IF(AND(C7="Cool",D7="Fast"),M6,IF(AND(C7="Warm",D7="Slow"),N6,O6))) | H7: =IF(F7="Overheated",0,IF(F7="Cool",MAX(L6,M6),MAX(N6,O6))) | I7: =E7+0.9*H7 | J7: =I7-G7 | K7: =G7+0.1*J7 | L7: =IF(AND(C7="Cool",D7="Slow"),K7,L6) | M7: =IF(AND(C7="Cool",D7="Fast"),K7,M6) | N7: =IF(AND(C7="Warm",D7="Slow"),K7,N6) | O7: =IF(AND(C7="Warm",D7="Fast"),K7,O6)
A8: 2 | B8: 1 | C8: Cool | D8: Fast | E8: 2 | F8: Cool | G8: =IF(AND(C8="Cool",D8="Slow"),L7,IF(AND(C8="Cool",D8="Fast"),M7,IF(AND(C8="Warm",D8="Slow"),N7,O7))) | H8: =IF(F8="Overheated",0,IF(F8="Cool",MAX(L7,M7),MAX(N7,O7))) | I8: =E8+0.9*H8 | J8: =I8-G8 | K8: =G8+0.1*J8 | L8: =IF(AND(C8="Cool",D8="Slow"),K8,L7) | M8: =IF(AND(C8="Cool",D8="Fast"),K8,M7) | N8: =IF(AND(C8="Warm",D8="Slow"),K8,N7) | O8: =IF(AND(C8="Warm",D8="Fast"),K8,O7)
A9: 3 | B9: 1 | C9: Cool | D9: Fast | E9: 2 | F9: Cool | G9: =IF(AND(C9="Cool",D9="Slow"),L8,IF(AND(C9="Cool",D9="Fast"),M8,IF(AND(C9="Warm",D9="Slow"),N8,O8))) | H9: =IF(F9="Overheated",0,IF(F9="Cool",MAX(L8,M8),MAX(N8,O8))) | I9: =E9+0.9*H9 | J9: =I9-G9 | K9: =G9+0.1*J9 | L9: =IF(AND(C9="Cool",D9="Slow"),K9,L8) | M9: =IF(AND(C9="Cool",D9="Fast"),K9,M8) | N9: =IF(AND(C9="Warm",D9="Slow"),K9,N8) | O9: =IF(AND(C9="Warm",D9="Fast"),K9,O8)
A10: 4 | B10: 1 | C10: Cool | D10: Fast | E10: 2 | F10: Cool | G10: =IF(AND(C10="Cool",D10="Slow"),L9,IF(AND(C10="Cool",D10="Fast"),M9,IF(AND(C10="Warm",D10="Slow"),N9,O9))) | H10: =IF(F10="Overheated",0,IF(F10="Cool",MAX(L9,M9),MAX(N9,O9))) | I10: =E10+0.9*H10 | J10: =I10-G10 | K10: =G10+0.1*J10 | L10: =IF(AND(C10="Cool",D10="Slow"),K10,L9) | M10: =IF(AND(C10="Cool",D10="Fast"),K10,M9) | N10: =IF(AND(C10="Warm",D10="Slow"),K10,N9) | O10: =IF(AND(C10="Warm",D10="Fast"),K10,O9)
A11: 5 | B11: 1 | C11: Cool | D11: Fast | E11: 2 | F11: Cool | G11: =IF(AND(C11="Cool",D11="Slow"),L10,IF(AND(C11="Cool",D11="Fast"),M10,IF(AND(C11="Warm",D11="Slow"),N10,O10))) | H11: =IF(F11="Overheated",0,IF(F11="Cool",MAX(L10,M10),MAX(N10,O10))) | I11: =E11+0.9*H11 | J11: =I11-G11 | K11: =G11+0.1*J11 | L11: =IF(AND(C11="Cool",D11="Slow"),K11,L10) | M11: =IF(AND(C11="Cool",D11="Fast"),K11,M10) | N11: =IF(AND(C11="Warm",D11="Slow"),K11,N10) | O11: =IF(AND(C11="Warm",D11="Fast"),K11,O10)
A12: 6 | B12: 1 | C12: Cool | D12: Fast | E12: 2 | F12: Cool | G12: =IF(AND(C12="Cool",D12="Slow"),L11,IF(AND(C12="Cool",D12="Fast"),M11,IF(AND(C12="Warm",D12="Slow"),N11,O11))) | H12: =IF(F12="Overheated",0,IF(F12="Cool",MAX(L11,M11),MAX(N11,O11))) | I12: =E12+0.9*H12 | J12: =I12-G12 | K12: =G12+0.1*J12 | L12: =IF(AND(C12="Cool",D12="Slow"),K12,L11) | M12: =IF(AND(C12="Cool",D12="Fast"),K12,M11) | N12: =IF(AND(C12="Warm",D12="Slow"),K12,N11) | O12: =IF(AND(C12="Warm",D12="Fast"),K12,O11)
A13: 7 | B13: 1 | C13: Cool | D13: Fast | E13: 2 | F13: Cool | G13: =IF(AND(C13="Cool",D13="Slow"),L12,IF(AND(C13="Cool",D13="Fast"),M12,IF(AND(C13="Warm",D13="Slow"),N12,O12))) | H13: =IF(F13="Overheated",0,IF(F13="Cool",MAX(L12,M12),MAX(N12,O12))) | I13: =E13+0.9*H13 | J13: =I13-G13 | K13: =G13+0.1*J13 | L13: =IF(AND(C13="Cool",D13="Slow"),K13,L12) | M13: =IF(AND(C13="Cool",D13="Fast"),K13,M12) | N13: =IF(AND(C13="Warm",D13="Slow"),K13,N12) | O13: =IF(AND(C13="Warm",D13="Fast"),K13,O12)
A14: 8 | B14: 1 | C14: Cool | D14: Fast | E14: 2 | F14: Warm | G14: =IF(AND(C14="Cool",D14="Slow"),L13,IF(AND(C14="Cool",D14="Fast"),M13,IF(AND(C14="Warm",D14="Slow"),N13,O13))) | H14: =IF(F14="Overheated",0,IF(F14="Cool",MAX(L13,M13),MAX(N13,O13))) | I14: =E14+0.9*H14 | J14: =I14-G14 | K14: =G14+0.1*J14 | L14: =IF(AND(C14="Cool",D14="Slow"),K14,L13) | M14: =IF(AND(C14="Cool",D14="Fast"),K14,M13) | N14: =IF(AND(C14="Warm",D14="Slow"),K14,N13) | O14: =IF(AND(C14="Warm",D14="Fast"),K14,O13)
A15: 9 | B15: 1 | C15: Warm | D15: Slow | E15: 1 | F15: Warm | G15: =IF(AND(C15="Cool",D15="Slow"),L14,IF(AND(C15="Cool",D15="Fast"),M14,IF(AND(C15="Warm",D15="Slow"),N14,O14))) | H15: =IF(F15="Overheated",0,IF(F15="Cool",MAX(L14,M14),MAX(N14,O14))) | I15: =E15+0.9*H15 | J15: =I15-G15 | K15: =G15+0.1*J15 | L15: =IF(AND(C15="Cool",D15="Slow"),K15,L14) | M15: =IF(AND(C15="Cool",D15="Fast"),K15,M14) | N15: =IF(AND(C15="Warm",D15="Slow"),K15,N14) | O15: =IF(AND(C15="Warm",D15="Fast"),K15,O14)
A16: 10 | B16: 1 | C16: Warm | D16: Slow | E16: 1 | F16: Cool | G16: =IF(AND(C16="Cool",D16="Slow"),L15,IF(AND(C16="Cool",D16="Fast"),M15,IF(AND(C16="Warm",D16="Slow"),N15,O15))) | H16: =IF(F16="Overheated",0,IF(F16="Cool",MAX(L15,M15),MAX(N15,O15))) | I16: =E16+0.9*H16 | J16: =I16-G16 | K16: =G16+0.1*J16 | L16: =IF(AND(C16="Cool",D16="Slow"),K16,L15) | M16: =IF(AND(C16="Cool",D16="Fast"),K16,M15) | N16: =IF(AND(C16="Warm",D16="Slow"),K16,N15) | O16: =IF(AND(C16="Warm",D16="Fast"),K16,O15)
A17: 11 | B17: 1 | C17: Cool | D17: Fast | E17: 2 | F17: Cool | G17: =IF(AND(C17="Cool",D17="Slow"),L16,IF(AND(C17="Cool",D17="Fast"),M16,IF(AND(C17="Warm",D17="Slow"),N16,O16))) | H17: =IF(F17="Overheated",0,IF(F17="Cool",MAX(L16,M16),MAX(N16,O16))) | I17: =E17+0.9*H17 | J17: =I17-G17 | K17: =G17+0.1*J17 | L17: =IF(AND(C17="Cool",D17="Slow"),K17,L16) | M17: =IF(AND(C17="Cool",D17="Fast"),K17,M16) | N17: =IF(AND(C17="Warm",D17="Slow"),K17,N16) | O17: =IF(AND(C17="Warm",D17="Fast"),K17,O16)
A18: 12 | B18: 1 | C18: Cool | D18: Fast | E18: 2 | F18: Warm | G18: =IF(AND(C18="Cool",D18="Slow"),L17,IF(AND(C18="Cool",D18="Fast"),M17,IF(AND(C18="Warm",D18="Slow"),N17,O17))) | H18: =IF(F18="Overheated",0,IF(F18="Cool",MAX(L17,M17),MAX(N17,O17))) | I18: =E18+0.9*H18 | J18: =I18-G18 | K18: =G18+0.1*J18 | L18: =IF(AND(C18="Cool",D18="Slow"),K18,L17) | M18: =IF(AND(C18="Cool",D18="Fast"),K18,M17) | N18: =IF(AND(C18="Warm",D18="Slow"),K18,N17) | O18: =IF(AND(C18="Warm",D18="Fast"),K18,O17)
